{
 "cells": [
  {
   "cell_type": "code",
   "execution_count": 20,
   "metadata": {},
   "outputs": [],
   "source": [
    "import pandas as pd\n",
    "import numpy as np\n",
    "\n",
    "import os\n",
    "import sys\n",
    "\n",
    "import librosa\n",
    "import librosa.display\n",
    "\n",
    "import seaborn as sns\n",
    "import matplotlib.pyplot as plt\n",
    "\n",
    "from sklearn.preprocessing import StandardScaler, OneHotEncoder\n",
    "from sklearn.metrics import confusion_matrix, classification_report\n",
    "from sklearn.model_selection import train_test_split\n",
    "from IPython.display import Audio\n",
    "import keras\n",
    "from keras.callbacks import ReduceLROnPlateau\n",
    "from keras.models import Sequential\n",
    "from keras.layers import Dense, Conv1D, MaxPooling1D, Flatten, Dropout, BatchNormalization\n",
    "from keras.utils import np_utils\n",
    "from tensorflow.keras.utils import to_categorical\n",
    "from tensorflow.keras.models import load_model\n",
    "\n",
    "from keras.callbacks import ModelCheckpoint\n",
    "\n",
    "import warnings\n",
    "if not sys.warnoptions:\n",
    "    warnings.simplefilter(\"ignore\")\n",
    "warnings.filterwarnings(\"ignore\", category=DeprecationWarning) \n"
   ]
  },
  {
   "cell_type": "code",
   "execution_count": 21,
   "metadata": {},
   "outputs": [
    {
     "name": "stdout",
     "output_type": "stream",
     "text": [
      "static\\savedFiles\\happy_1_2.wav\n"
     ]
    }
   ],
   "source": [
    "audioFile = \"static\\savedFiles\\happy_1_2.wav\"\n",
    "model = load_model(\"models\\modelcnncsvtrial.h5\")\n",
    "model.make_predict_function()\n",
    "print(audioFile)"
   ]
  },
  {
   "cell_type": "code",
   "execution_count": 22,
   "metadata": {},
   "outputs": [
    {
     "name": "stdout",
     "output_type": "stream",
     "text": [
      "[-0.00542669 -0.00953117 -0.00950526 ... -0.00589577 -0.00520898\n",
      "  0.        ]\n"
     ]
    }
   ],
   "source": [
    "sample_rate=22050\n",
    "x, sr = librosa.load(audioFile, sample_rate)\n",
    "print(x)"
   ]
  },
  {
   "cell_type": "code",
   "execution_count": 23,
   "metadata": {},
   "outputs": [
    {
     "data": {
      "text/plain": [
       "(176295,)"
      ]
     },
     "execution_count": 23,
     "metadata": {},
     "output_type": "execute_result"
    }
   ],
   "source": [
    "x.shape"
   ]
  },
  {
   "cell_type": "code",
   "execution_count": 24,
   "metadata": {},
   "outputs": [],
   "source": [
    "chroma_stft = np.mean(librosa.feature.chroma_stft(y=x))\n",
    "result = np.array([])\n",
    "\n",
    "mel = np.mean(librosa.feature.melspectrogram(y=x, sr=sr))\n",
    "result = np.hstack((result, mel))\n",
    "\n",
    "mfcc = np.mean(librosa.feature.mfcc(y=x, sr=sr))\n",
    "result = np.hstack((result, mfcc))\n"
   ]
  },
  {
   "cell_type": "code",
   "execution_count": 25,
   "metadata": {},
   "outputs": [
    {
     "name": "stdout",
     "output_type": "stream",
     "text": [
      "[  0.31754154 -24.11108208]\n"
     ]
    }
   ],
   "source": [
    "print(result)\n",
    "# print(result.shape)"
   ]
  },
  {
   "cell_type": "code",
   "execution_count": 26,
   "metadata": {},
   "outputs": [
    {
     "name": "stdout",
     "output_type": "stream",
     "text": [
      "WARNING:tensorflow:Model was constructed with shape (None, 162, 1) for input KerasTensor(type_spec=TensorSpec(shape=(None, 162, 1), dtype=tf.float32, name='conv1d_20_input'), name='conv1d_20_input', description=\"created by layer 'conv1d_20_input'\"), but it was called on an input with incompatible shape (None,).\n"
     ]
    },
    {
     "ename": "ValueError",
     "evalue": "in user code:\n\n    File \"C:\\Users\\Swapnil\\AppData\\Local\\Programs\\Python\\Python310\\lib\\site-packages\\keras\\engine\\training.py\", line 1801, in predict_function  *\n        return step_function(self, iterator)\n    File \"C:\\Users\\Swapnil\\AppData\\Local\\Programs\\Python\\Python310\\lib\\site-packages\\keras\\engine\\training.py\", line 1790, in step_function  **\n        outputs = model.distribute_strategy.run(run_step, args=(data,))\n    File \"C:\\Users\\Swapnil\\AppData\\Local\\Programs\\Python\\Python310\\lib\\site-packages\\keras\\engine\\training.py\", line 1783, in run_step  **\n        outputs = model.predict_step(data)\n    File \"C:\\Users\\Swapnil\\AppData\\Local\\Programs\\Python\\Python310\\lib\\site-packages\\keras\\engine\\training.py\", line 1751, in predict_step\n        return self(x, training=False)\n    File \"C:\\Users\\Swapnil\\AppData\\Local\\Programs\\Python\\Python310\\lib\\site-packages\\keras\\utils\\traceback_utils.py\", line 67, in error_handler\n        raise e.with_traceback(filtered_tb) from None\n    File \"C:\\Users\\Swapnil\\AppData\\Local\\Programs\\Python\\Python310\\lib\\site-packages\\keras\\engine\\input_spec.py\", line 228, in assert_input_compatibility\n        raise ValueError(f'Input {input_index} of layer \"{layer_name}\" '\n\n    ValueError: Exception encountered when calling layer \"sequential_5\" (type Sequential).\n    \n    Input 0 of layer \"conv1d_20\" is incompatible with the layer: expected min_ndim=3, found ndim=1. Full shape received: (None,)\n    \n    Call arguments received:\n      • inputs=tf.Tensor(shape=(None,), dtype=float32)\n      • training=False\n      • mask=None\n",
     "output_type": "error",
     "traceback": [
      "\u001b[1;31m---------------------------------------------------------------------------\u001b[0m",
      "\u001b[1;31mValueError\u001b[0m                                Traceback (most recent call last)",
      "\u001b[1;32mc:\\Users\\Swapnil\\Desktop\\WebApp\\test.ipynb Cell 7'\u001b[0m in \u001b[0;36m<cell line: 1>\u001b[1;34m()\u001b[0m\n\u001b[1;32m----> <a href='vscode-notebook-cell:/c%3A/Users/Swapnil/Desktop/WebApp/test.ipynb#ch0000009?line=0'>1</a>\u001b[0m res \u001b[39m=\u001b[39m model\u001b[39m.\u001b[39;49mpredict(result)\n",
      "File \u001b[1;32m~\\AppData\\Local\\Programs\\Python\\Python310\\lib\\site-packages\\keras\\utils\\traceback_utils.py:67\u001b[0m, in \u001b[0;36mfilter_traceback.<locals>.error_handler\u001b[1;34m(*args, **kwargs)\u001b[0m\n\u001b[0;32m     <a href='file:///c%3A/Users/Swapnil/AppData/Local/Programs/Python/Python310/lib/site-packages/keras/utils/traceback_utils.py?line=64'>65</a>\u001b[0m \u001b[39mexcept\u001b[39;00m \u001b[39mException\u001b[39;00m \u001b[39mas\u001b[39;00m e:  \u001b[39m# pylint: disable=broad-except\u001b[39;00m\n\u001b[0;32m     <a href='file:///c%3A/Users/Swapnil/AppData/Local/Programs/Python/Python310/lib/site-packages/keras/utils/traceback_utils.py?line=65'>66</a>\u001b[0m   filtered_tb \u001b[39m=\u001b[39m _process_traceback_frames(e\u001b[39m.\u001b[39m__traceback__)\n\u001b[1;32m---> <a href='file:///c%3A/Users/Swapnil/AppData/Local/Programs/Python/Python310/lib/site-packages/keras/utils/traceback_utils.py?line=66'>67</a>\u001b[0m   \u001b[39mraise\u001b[39;00m e\u001b[39m.\u001b[39mwith_traceback(filtered_tb) \u001b[39mfrom\u001b[39;00m \u001b[39mNone\u001b[39m\n\u001b[0;32m     <a href='file:///c%3A/Users/Swapnil/AppData/Local/Programs/Python/Python310/lib/site-packages/keras/utils/traceback_utils.py?line=67'>68</a>\u001b[0m \u001b[39mfinally\u001b[39;00m:\n\u001b[0;32m     <a href='file:///c%3A/Users/Swapnil/AppData/Local/Programs/Python/Python310/lib/site-packages/keras/utils/traceback_utils.py?line=68'>69</a>\u001b[0m   \u001b[39mdel\u001b[39;00m filtered_tb\n",
      "File \u001b[1;32m~\\AppData\\Local\\Programs\\Python\\Python310\\lib\\site-packages\\tensorflow\\python\\framework\\func_graph.py:1147\u001b[0m, in \u001b[0;36mfunc_graph_from_py_func.<locals>.autograph_handler\u001b[1;34m(*args, **kwargs)\u001b[0m\n\u001b[0;32m   <a href='file:///c%3A/Users/Swapnil/AppData/Local/Programs/Python/Python310/lib/site-packages/tensorflow/python/framework/func_graph.py?line=1144'>1145</a>\u001b[0m \u001b[39mexcept\u001b[39;00m \u001b[39mException\u001b[39;00m \u001b[39mas\u001b[39;00m e:  \u001b[39m# pylint:disable=broad-except\u001b[39;00m\n\u001b[0;32m   <a href='file:///c%3A/Users/Swapnil/AppData/Local/Programs/Python/Python310/lib/site-packages/tensorflow/python/framework/func_graph.py?line=1145'>1146</a>\u001b[0m   \u001b[39mif\u001b[39;00m \u001b[39mhasattr\u001b[39m(e, \u001b[39m\"\u001b[39m\u001b[39mag_error_metadata\u001b[39m\u001b[39m\"\u001b[39m):\n\u001b[1;32m-> <a href='file:///c%3A/Users/Swapnil/AppData/Local/Programs/Python/Python310/lib/site-packages/tensorflow/python/framework/func_graph.py?line=1146'>1147</a>\u001b[0m     \u001b[39mraise\u001b[39;00m e\u001b[39m.\u001b[39mag_error_metadata\u001b[39m.\u001b[39mto_exception(e)\n\u001b[0;32m   <a href='file:///c%3A/Users/Swapnil/AppData/Local/Programs/Python/Python310/lib/site-packages/tensorflow/python/framework/func_graph.py?line=1147'>1148</a>\u001b[0m   \u001b[39melse\u001b[39;00m:\n\u001b[0;32m   <a href='file:///c%3A/Users/Swapnil/AppData/Local/Programs/Python/Python310/lib/site-packages/tensorflow/python/framework/func_graph.py?line=1148'>1149</a>\u001b[0m     \u001b[39mraise\u001b[39;00m\n",
      "\u001b[1;31mValueError\u001b[0m: in user code:\n\n    File \"C:\\Users\\Swapnil\\AppData\\Local\\Programs\\Python\\Python310\\lib\\site-packages\\keras\\engine\\training.py\", line 1801, in predict_function  *\n        return step_function(self, iterator)\n    File \"C:\\Users\\Swapnil\\AppData\\Local\\Programs\\Python\\Python310\\lib\\site-packages\\keras\\engine\\training.py\", line 1790, in step_function  **\n        outputs = model.distribute_strategy.run(run_step, args=(data,))\n    File \"C:\\Users\\Swapnil\\AppData\\Local\\Programs\\Python\\Python310\\lib\\site-packages\\keras\\engine\\training.py\", line 1783, in run_step  **\n        outputs = model.predict_step(data)\n    File \"C:\\Users\\Swapnil\\AppData\\Local\\Programs\\Python\\Python310\\lib\\site-packages\\keras\\engine\\training.py\", line 1751, in predict_step\n        return self(x, training=False)\n    File \"C:\\Users\\Swapnil\\AppData\\Local\\Programs\\Python\\Python310\\lib\\site-packages\\keras\\utils\\traceback_utils.py\", line 67, in error_handler\n        raise e.with_traceback(filtered_tb) from None\n    File \"C:\\Users\\Swapnil\\AppData\\Local\\Programs\\Python\\Python310\\lib\\site-packages\\keras\\engine\\input_spec.py\", line 228, in assert_input_compatibility\n        raise ValueError(f'Input {input_index} of layer \"{layer_name}\" '\n\n    ValueError: Exception encountered when calling layer \"sequential_5\" (type Sequential).\n    \n    Input 0 of layer \"conv1d_20\" is incompatible with the layer: expected min_ndim=3, found ndim=1. Full shape received: (None,)\n    \n    Call arguments received:\n      • inputs=tf.Tensor(shape=(None,), dtype=float32)\n      • training=False\n      • mask=None\n"
     ]
    }
   ],
   "source": [
    "\n",
    "res = model.predict(result)"
   ]
  }
 ],
 "metadata": {
  "interpreter": {
   "hash": "7779564e65ec684aa5be28d5a203a2dcb15106a4f4ecff7ccd1625c90ae7742a"
  },
  "kernelspec": {
   "display_name": "Python 3.10.3 64-bit",
   "language": "python",
   "name": "python3"
  },
  "language_info": {
   "codemirror_mode": {
    "name": "ipython",
    "version": 3
   },
   "file_extension": ".py",
   "mimetype": "text/x-python",
   "name": "python",
   "nbconvert_exporter": "python",
   "pygments_lexer": "ipython3",
   "version": "3.10.3"
  },
  "orig_nbformat": 4
 },
 "nbformat": 4,
 "nbformat_minor": 2
}
